Workbook

Sheet Executive_Summary
A1: Strategic Portfolio Optimization — Executive Summary
E14: Key Metrics Panel
E15: Metric | F15: Results
E16: Capital Reallocation | F16: ='Capital Reallocation Model'!B22 -> 10574775
E17: Old Blended Return | F17: ='Capital Reallocation Model'!B31 -> 0.026220547
E18: New IRR | F18: ='Capital Reallocation Model'!B30 -> 0.12190779
E19: Return Improvement | F19: =F18/F17 -> 4.6493228
E20: Portolio Risk | F20: ↓ Reduced

Sheet Portfolio_Summary(Weighted ROI)
A3: Portfolio Summary | E3: Before vs After Comparison Table (Risk Score Basis)
A4: Total Purchase Price | B4: =SUM(PortfolioData[Purchase_Price]) -> 2168175660 | E4: Metric | G4: Before | H4: After
A5: Weighted ROI Numerator | B5: =SUMPRODUCT(PortfolioData[ROI], PortfolioData[Purchase_Price]) -> 4.4177794e+08 | E5: Weighted Portfolio ROI | G5: =B6 -> 0.20375561 | H5: ↑ Improving
A6: Weighted Portfolio ROI | B6: =B5/B4 -> 0.20375561 | E6: Average Risk Score | G6: =AVERAGE(PortfolioData[Risk_Score]) -> 0.26601634 | H6: =Portfolio_Data!AH15 -> 0.26201602
E7: Worst Asset ROI | G7: =Portfolio_Data!Y2 -> -0.030174933 | H7: =Portfolio_Data!Y3 -> 0.25578913
E8: Blended ROI of Divested Assets | G8: ='Capital Reallocation Model'!B31 -> 0.026220547 | H8: N/A
E9: Projected IRR | G9: N/A | H9: ='Capital Reallocation Model'!B30 -> 0.12190779

Sheet Diagnostic_Analysis
B2: City-Level Performance Benchmarking | K2: Risk Heatmap
A3: City | B3: Average of ROI | C3: Average of Vacancy_% | D3: Average of DSCR | E3: Average of Cap Rate | I3: City | J3: Average of ROI | K3: Average of Vacancy_% | L3: Average of Debt_Ratio | M3: Average of DSCR
A4: Adelaide | B4: 0.19727324 | C4: 0.14606808 | D4: 2.6381504 | E4: 0.059929844 | I4: Adelaide | J4: 0.19727324 | K4: 0.14606808 | L4: 0.6909958 | M4: 2.6381504
A5: Brisbane | B5: 0.20906026 | C5: 0.1530365 | D5: 1.9659957 | E5: 0.039810295 | I5: Brisbane | J5: 0.20906026 | K5: 0.1530365 | L5: 0.55952117 | M5: 1.9659957
A6: Melbourne | B6: 0.24751112 | C6: 0.14299013 | D6: 3.5952373 | E6: 0.074561511 | I6: Melbourne | J6: 0.24751112 | K6: 0.14299013 | L6: 0.71846193 | M6: 3.5952373
A7: Perth | B7: 0.22061349 | C7: 0.13507721 | D7: 3.4016879 | E7: 0.057128666 | I7: Perth | J7: 0.22061349 | K7: 0.13507721 | L7: 0.53730872 | M7: 3.4016879
A8: Sydney | B8: 0.17283032 | C8: 0.1660513 | D8: 4.1581678 | E8: 0.073291863 | I8: Sydney | J8: 0.17283032 | K8: 0.1660513 | L8: 0.64353171 | M8: 4.1581678
A9: Grand Total | B9: 0.21000309 | C9: 0.14888264 | D9: 3.1964186 | E9: 0.061818383 | I9: Grand Total | J9: 0.21000309 | K9: 0.14888264 | L9: 0.6338656 | M9: 3.1964186
B12: Property Type Performance Breakdown
A13: Type | B13: Average of ROI | C13: Average of Vacancy_% | D13: Average of Net Operating Income (NOI) | I13: City Risk Ranking
A14: Mixed-use | B14: 0.20341964 | C14: 0.15245185 | D14: 879373.51 | I14: City | J14: Average of Risk_Score
A15: Office | B15: 0.23383285 | C15: 0.1175502 | D15: 1050267.5 | I15: Adelaide | J15: 0.34386599
A16: Retail | B16: 0.20644099 | C16: 0.16814232 | D16: 875964.39 | I16: Brisbane | J16: 0.083763518
A17: Warehouse | B17: 0.20132022 | C17: 0.15282106 | D17: 733834.22 | I17: Melbourne | J17: 0.18488904
A18: Grand Total | B18: 0.21000309 | C18: 0.14888264 | D18: 871350.92 | I18: Perth | J18: 0.35570295
I19: Sydney | J19: -0.73881858
I20: Grand Total | J20: 0.030515609
C21: Debt Burden Diagnosis
A22: Performance_Flag | B22: Average of Debt_Ratio | C22: Average of DSCR | D22: Average of Vacancy_% | E22: Average of Cap Rate
A23: Healthy | B23: 0.6046617 | C23: 3.5887155 | D23: 0.14452146 | E23: 0.071045831
A24: Underperforming | B24: 0.87844829 | C24: -0.089067637 | D24: 0.18540752 | E24: -0.015461494
A25: Grand Total | B25: 0.6338656 | C25: 3.1964186 | D25: 0.14888264 | E25: 0.061818383
B27: Vacancy Contribution Check
A28: Performance_Flag | B28: Average of Vacancy_% | C28: Average of Vacancy_Loss_% | D28: Average of ROI
A29: Healthy | B29: 0.14452146 | C29: 0.14452146 | D29: 0.24345067
A30: Underperforming | B30: 0.18540752 | C30: 0.18540752 | D30: -0.070120374
A31: Grand Total | B31: 0.14888264 | C31: 0.14888264 | D31: 0.21000309
A33: City | B33: Average of Vacancy_Loss_% | C33: Average of ROI
A34: Adelaide | B34: 0.14606808 | C34: 0.19727324
A35: Brisbane | B35: 0.1530365 | C35: 0.20906026
A36: Melbourne | B36: 0.14299013 | C36: 0.24751112
A37: Perth | B37: 0.13507721 | C37: 0.22061349
A38: Sydney | B38: 0.1660513 | C38: 0.17283032
A39: Grand Total | B39: 0.14888264 | C39: 0.21000309

Sheet Capital Reallocation Model
A1: Property_ID | B1: City | C1: Type | D1: Acquisition_Year | E1: Purchase_Price | F1: Current_Value | G1: Units | H1: Occupied_Units | I1: Avg_Rent_per_Unit | J1: Operating_Cost | K1: Maintenance_Cost | L1: Debt_Outstanding | M1: Interest_Rate | N1: Lease_Type | O1: Gross_Rental_Income | P1: Vacancy_% | Q1: Net Operating Income (NOI) | R1: Annual_Debt_Service | S1: Adjusted_Debt_Outstanding | T1: DSCR | U1: Free_Cash_Flow | V1: EBITDA | W1: Gross Yield | X1: Cap_rate | Y1: ROI | Z1: ROI_Percentile | AA1: Performance_Flag | AB1: Debt_Ratio | AC1: Potential_Revenue | AD1: Vacancy_Loss | AE1: Vacancy_Loss_% | AF1: Risk_Score
A2: P102 | B2: Sydney | C2: Warehouse | D2: 2020 | E2: 5926551 | F2: 5477928.7 | G2: 71 | H2: 57 | I2: 1573 | J2: 422066 | K2: 384077 | L2: 13983693 | M2: 5.79 | N2: Short-term | O2: =PortfolioData[[#This Row],[Occupied_Units]]*PortfolioData[[#This Row],[Avg_Rent_per_Unit]]*12 -> 1075932 | P2: =1-(PortfolioData[[#This Row],[Occupied_Units]]/PortfolioData[[#This Row],[Units]]) -> 0.1971831 | Q2: =PortfolioData[[#This Row],[Gross_Rental_Income]] - PortfolioData[[#This Row],[Operating_Cost]] - PortfolioData[[#This Row],[Maintenance_Cost]] -> 269789 | R2: =PortfolioData[[#This Row],[Adjusted_Debt_Outstanding]]*(PortfolioData[[#This Row],[Interest_Rate]]/100) -> 253737.66 | S2: =MIN(PortfolioData[[#This Row],[Debt_Outstanding]], PortfolioData[[#This Row],[Current_Value]]*0.8) -> 4382343 | T2: =PortfolioData[[#This Row],[Net Operating Income (NOI)]]/PortfolioData[[#This Row],[Annual_Debt_Service]] -> 1.0632596 | U2: =PortfolioData[[#This Row],[Net Operating Income (NOI)]]-PortfolioData[[#This Row],[Annual_Debt_Service]] -> 16051.342 | V2: =PortfolioData[[#This Row],[Net Operating Income (NOI)]] -> 269789 | W2: =PortfolioData[[#This Row],[Gross_Rental_Income]] / PortfolioData[[#This Row],[Purchase_Price]] -> 0.18154438 | X2: =PortfolioData[[#This Row],[Net Operating Income (NOI)]]/PortfolioData[[#This Row],[Current_Value]] -> 0.049250184 | Y2: =(PortfolioData[[#This Row],[Current_Value]]-PortfolioData[[#This Row],[Purchase_Price]]+PortfolioData[[#This Row],[Net Operating Income (NOI)]]) / PortfolioData[[#This Row],[Purchase_Price]] -> -0.030174933 | Z2: =_xlfn.PERCENTRANK.INC(PortfolioData[ROI],PortfolioData[[#This Row],[ROI]]) -> 0.127 | AA2: =IF(PortfolioData[[#This Row],[ROI_Percentile]]<=0.1,"Underperforming","Healthy") -> Healthy | AB2: =PortfolioData[[#This Row],[Debt_Outstanding]]/PortfolioData[[#This Row],[Current_Value]] -> 2.5527337 | AC2: =PortfolioData[[#This Row],[Units]]*PortfolioData[[#This Row],[Avg_Rent_per_Unit]]*12 -> 1340196 | AD2: =PortfolioData[[#This Row],[Potential_Revenue]]-PortfolioData[[#This Row],[Gross_Rental_Income]] -> 264264 | AE2: =IFERROR(PortfolioData[[#This Row],[Vacancy_Loss]]/PortfolioData[[#This Row],[Potential_Revenue]],0) -> 0.1971831 | AF2: =(PortfolioData[[#This Row],[Vacancy_%]] * 0.4) + (PortfolioData[[#This Row],[Debt_Ratio]] * 0.3) + (PortfolioData[[#This Row],[Interest_Rate]]/100 * 0.3) -> 0.86206334
A3: P143 | B3: Adelaide | C3: Mixed-use | D3: 2020 | E3: 5131150 | F3: 5251723.4 | G3: 57 | H3: 42 | I3: 4135 | J3: 453835 | K3: 438286 | L3: 12882576 | M3: 3.69 | N3: Long-term | O3: =PortfolioData[[#This Row],[Occupied_Units]]*PortfolioData[[#This Row],[Avg_Rent_per_Unit]]*12 -> 2084040 | P3: =1-(PortfolioData[[#This Row],[Occupied_Units]]/PortfolioData[[#This Row],[Units]]) -> 0.26315789 | Q3: =PortfolioData[[#This Row],[Gross_Rental_Income]] - PortfolioData[[#This Row],[Operating_Cost]] - PortfolioData[[#This Row],[Maintenance_Cost]] -> 1191919 | R3: =PortfolioData[[#This Row],[Adjusted_Debt_Outstanding]]*(PortfolioData[[#This Row],[Interest_Rate]]/100) -> 155030.88 | S3: =MIN(PortfolioData[[#This Row],[Debt_Outstanding]], PortfolioData[[#This Row],[Current_Value]]*0.8) -> 4201378.7 | T3: =PortfolioData[[#This Row],[Net Operating Income (NOI)]]/PortfolioData[[#This Row],[Annual_Debt_Service]] -> 7.6882685 | U3: =PortfolioData[[#This Row],[Net Operating Income (NOI)]]-PortfolioData[[#This Row],[Annual_Debt_Service]] -> 1036888.1 | V3: =PortfolioData[[#This Row],[Net Operating Income (NOI)]] -> 1191919 | W3: =PortfolioData[[#This Row],[Gross_Rental_Income]] / PortfolioData[[#This Row],[Purchase_Price]] -> 0.40615457 | X3: =PortfolioData[[#This Row],[Net Operating Income (NOI)]]/PortfolioData[[#This Row],[Current_Value]] -> 0.22695769 | Y3: =(PortfolioData[[#This Row],[Current_Value]]-PortfolioData[[#This Row],[Purchase_Price]]+PortfolioData[[#This Row],[Net Operating Income (NOI)]]) / PortfolioData[[#This Row],[Purchase_Price]] -> 0.25578913 | Z3: =_xlfn.PERCENTRANK.INC(PortfolioData[ROI],PortfolioData[[#This Row],[ROI]]) -> 0.57 | AA3: =IF(PortfolioData[[#This Row],[ROI_Percentile]]<=0.1,"Underperforming","Healthy") -> Healthy | AB3: =PortfolioData[[#This Row],[Debt_Outstanding]]/PortfolioData[[#This Row],[Current_Value]] -> 2.4530188 | AC3: =PortfolioData[[#This Row],[Units]]*PortfolioData[[#This Row],[Avg_Rent_per_Unit]]*12 -> 2828340 | AD3: =PortfolioData[[#This Row],[Potential_Revenue]]-PortfolioData[[#This Row],[Gross_Rental_Income]] -> 744300 | AE3: =IFERROR(PortfolioData[[#This Row],[Vacancy_Loss]]/PortfolioData[[#This Row],[Potential_Revenue]],0) -> 0.26315789 | AF3: =(PortfolioData[[#This Row],[Vacancy_%]] * 0.4) + (PortfolioData[[#This Row],[Debt_Ratio]] * 0.3) + (PortfolioData[[#This Row],[Interest_Rate]]/100 * 0.3) -> 0.85223878
A4: P100 | B4: Melbourne | C4: Retail | D4: 2016 | E4: 5300981 | F4: 5096846 | G4: 66 | H4: 46 | I4: 2414 | J4: 221485 | K4: 468962 | L4: 11028997 | M4: 4.57 | N4: Long-term | O4: =PortfolioData[[#This Row],[Occupied_Units]]*PortfolioData[[#This Row],[Avg_Rent_per_Unit]]*12 -> 1332528 | P4: =1-(PortfolioData[[#This Row],[Occupied_Units]]/PortfolioData[[#This Row],[Units]]) -> 0.3030303 | Q4: =PortfolioData[[#This Row],[Gross_Rental_Income]] - PortfolioData[[#This Row],[Operating_Cost]] - PortfolioData[[#This Row],[Maintenance_Cost]] -> 642081 | R4: =PortfolioData[[#This Row],[Adjusted_Debt_Outstanding]]*(PortfolioData[[#This Row],[Interest_Rate]]/100) -> 186340.69 | S4: =MIN(PortfolioData[[#This Row],[Debt_Outstanding]], PortfolioData[[#This Row],[Current_Value]]*0.8) -> 4077476.8 | T4: =PortfolioData[[#This Row],[Net Operating Income (NOI)]]/PortfolioData[[#This Row],[Annual_Debt_Service]] -> 3.445737 | U4: =PortfolioData[[#This Row],[Net Operating Income (NOI)]]-PortfolioData[[#This Row],[Annual_Debt_Service]] -> 455740.31 | V4: =PortfolioData[[#This Row],[Net Operating Income (NOI)]] -> 642081 | W4: =PortfolioData[[#This Row],[Gross_Rental_Income]] / PortfolioData[[#This Row],[Purchase_Price]] -> 0.25137385 | X4: =PortfolioData[[#This Row],[Net Operating Income (NOI)]]/PortfolioData[[#This Row],[Current_Value]] -> 0.12597614 | Y4: =(PortfolioData[[#This Row],[Current_Value]]-PortfolioData[[#This Row],[Purchase_Price]]+PortfolioData[[#This Row],[Net Operating Income (NOI)]]) / PortfolioData[[#This Row],[Purchase_Price]] -> 0.082616027 | Z4: =_xlfn.PERCENTRANK.INC(PortfolioData[ROI],PortfolioData[[#This Row],[ROI]]) -> 0.302 | AA4: =IF(PortfolioData[[#This Row],[ROI_Percentile]]<=0.1,"Underperforming","Healthy") -> Healthy | AB4: =PortfolioData[[#This Row],[Debt_Outstanding]]/PortfolioData[[#This Row],[Current_Value]] -> 2.1638867 | AC4: =PortfolioData[[#This Row],[Units]]*PortfolioData[[#This Row],[Avg_Rent_per_Unit]]*12 -> 1911888 | AD4: =PortfolioData[[#This Row],[Potential_Revenue]]-PortfolioData[[#This Row],[Gross_Rental_Income]] -> 579360 | AE4: =IFERROR(PortfolioData[[#This Row],[Vacancy_Loss]]/PortfolioData[[#This Row],[Potential_Revenue]],0) -> 0.3030303 | AF4: =(PortfolioData[[#This Row],[Vacancy_%]] * 0.4) + (PortfolioData[[#This Row],[Debt_Ratio]] * 0.3) + (PortfolioData[[#This Row],[Interest_Rate]]/100 * 0.3) -> 0.78408812
A6: Total_Reinvested_Captal | B6: =SUM(F2:F4) -> 15826498
A9: Scenario 1 - Reinvested Capital into Brisbane | B9: Cash Flow | M9: Cap_Rate vs Rental Growth
A10: Year | B10: Cash Flow | M10: Selected_City | N10: Brisbane
A11: 0 | B11: =-B6 -> -15826498 | M11: Cap_Rate | N11: {=_xlfn.XLOOKUP(N10,Table2[[#All],[City]],Table2[[#All],[Cap_Rate_%]])} -> 6.66
A12: 1 | B12: =B6*0.0666 -> 1054044.8 | M12: Rental_Growth | N12: {=_xlfn.XLOOKUP(N10,Table2[[#All],[City]],Table2[[#All],[Rental_Growth_%]])} -> 6.75
A13: 2 | B13: =B12*(1+ 6.75%) -> 1125192.8
A14: 3 | B14: =B13*(1+ 6.75%) -> 1201143.3
A15: 4 | B15: =B14*(1+ 6.75%) -> 1282220.5 | H15: 1368770.4
A16: 5 | B16: =(H15/0.0666)+H15 -> 21920878
A17: IRR | B17: =IRR(B11:B16) -> 0.12190779
A18: Average ROI | B18: =AVERAGE(Y2:Y4) -> 0.10274341
A21: Recalculated_Reinvested_Capital - Brisbane | B21: Cash Flow
A22: Selective_Reinvestment_Capital | B22: =F2+F4 -> 10574775
A23: Year | B23: Cash Flow
A24: 0 | B24: =-B22 -> -10574775
A25: 1 | B25: =B22*0.0666 -> 704280
A26: 2 | B26: =B25*(1+ 6.75%) -> 751818.9
A27: 3 | B27: =B26*(1+ 6.75%) -> 802566.67
A28: 4 | B28: =B27*(1+ 6.75%) -> 856739.92
A29: 5 | B29: =(B32/F35)+B32 -> 14646850 | H29: =SUM(H27:H28) -> 0
A30: IRR | B30: =IRR(B24:B29) -> 0.12190779
A31: Average ROI | B31: =AVERAGE(Portfolio_Data!Y2,Portfolio_Data!Y4) -> 0.026220547
A32: 5th Year NOI | B32: =B28*(1+ 6.75%) -> 914569.87
A34: Sensitivity Analysis
A35: Cap Rate | B35: IRR | D35: Scenario Cap Rate | F35: =Market_Indicators!D4/100 -> 0.0666
A36: 0.06 | B36: =IRR(CHOOSE({1,2,3,4,5,6},$B$24,$B$25,$B$26,$B$27,$B$28,$B$32+($B$32/A36))) -> 0.14150037
A37: 0.0625 | B37: =IRR(CHOOSE({1,2,3,4,5,6},$B$24,$B$25,$B$26,$B$27,$B$28,$B$32+($B$32/A37))) -> 0.13376434
A38: 0.065 | B38: =IRR(CHOOSE({1,2,3,4,5,6},$B$24,$B$25,$B$26,$B$27,$B$28,$B$32+($B$32/A38))) -> 0.12641906
A39: 0.0666 | B39: =IRR(CHOOSE({1,2,3,4,5,6},$B$24,$B$25,$B$26,$B$27,$B$28,$B$32+($B$32/A39))) -> 0.12190779
A40: 0.07 | B40: =IRR(CHOOSE({1,2,3,4,5,6},$B$24,$B$25,$B$26,$B$27,$B$28,$B$32+($B$32/A40))) -> 0.11277304
A41: 0.075 | B41: =IRR(CHOOSE({1,2,3,4,5,6},$B$24,$B$25,$B$26,$B$27,$B$28,$B$32+($B$32/A41))) -> 0.10034205
A42: 0.08 | B42: =IRR(CHOOSE({1,2,3,4,5,6},$B$24,$B$25,$B$26,$B$27,$B$28,$B$32+($B$32/A42))) -> 0.088951349

Sheet Portfolio_Data
A1: Property_ID | B1: City | C1: Type | D1: Acquisition_Year | E1: Purchase_Price | F1: Current_Value | G1: Units | H1: Occupied_Units | I1: Avg_Rent_per_Unit | J1: Operating_Cost | K1: Maintenance_Cost | L1: Debt_Outstanding | M1: Interest_Rate | N1: Lease_Type | O1: Gross_Rental_Income | P1: Vacancy_% | Q1: Net Operating Income (NOI) | R1: Annual_Debt_Service | S1: Adjusted_Debt_Outstanding | T1: DSCR | U1: Free_Cash_Flow | V1: EBITDA | W1: Gross Yield | X1: Cap Rate | Y1: ROI | Z1: ROI_Percentile | AA1: Performance_Flag | AB1: Debt_Ratio | AC1: Potential_Revenue | AD1: Vacancy_Loss | AE1: Vacancy_Loss_% | AF1: Risk_Score
A2: P102 | B2: Sydney | C2: Warehouse | D2: 2020 | E2: 5926551 | F2: 5477928.7 | G2: 71 | H2: 57 | I2: 1573 | J2: 422066 | K2: 384077 | L2: 13983693 | M2: 5.79 | N2: Short-term | O2: =PortfolioData[[#This Row],[Occupied_Units]]*PortfolioData[[#This Row],[Avg_Rent_per_Unit]]*12 -> 1075932 | P2: =1-(PortfolioData[[#This Row],[Occupied_Units]]/PortfolioData[[#This Row],[Units]]) -> 0.1971831 | Q2: =PortfolioData[[#This Row],[Gross_Rental_Income]] - PortfolioData[[#This Row],[Operating_Cost]] - PortfolioData[[#This Row],[Maintenance_Cost]] -> 269789 | R2: =PortfolioData[[#This Row],[Adjusted_Debt_Outstanding]]*(PortfolioData[[#This Row],[Interest_Rate]]/100) -> 253737.66 | S2: =MIN(PortfolioData[[#This Row],[Debt_Outstanding]], PortfolioData[[#This Row],[Current_Value]]*0.8) -> 4382343 | T2: =PortfolioData[[#This Row],[Net Operating Income (NOI)]]/PortfolioData[[#This Row],[Annual_Debt_Service]] -> 1.0632596 | U2: =PortfolioData[[#This Row],[Net Operating Income (NOI)]]-PortfolioData[[#This Row],[Annual_Debt_Service]] -> 16051.342 | V2: =PortfolioData[[#This Row],[Net Operating Income (NOI)]] -> 269789 | W2: =PortfolioData[[#This Row],[Gross_Rental_Income]] / PortfolioData[[#This Row],[Purchase_Price]] -> 0.18154438 | X2: =PortfolioData[[#This Row],[Net Operating Income (NOI)]]/PortfolioData[[#This Row],[Current_Value]] -> 0.049250184 | Y2: =(PortfolioData[[#This Row],[Current_Value]]-PortfolioData[[#This Row],[Purchase_Price]]+PortfolioData[[#This Row],[Net Operating Income (NOI)]]) / PortfolioData[[#This Row],[Purchase_Price]] -> -0.030174933 | Z2: =_xlfn.PERCENTRANK.INC(PortfolioData[ROI],PortfolioData[[#This Row],[ROI]]) -> 0.127 | AA2: =IF(PortfolioData[[#This Row],[ROI_Percentile]]<=0.1,"Underperforming","Healthy") -> Healthy | AB2: =PortfolioData[[#This Row],[Debt_Outstanding]]/PortfolioData[[#This Row],[Current_Value]] -> 2.5527337 | AC2: =PortfolioData[[#This Row],[Units]]*PortfolioData[[#This Row],[Avg_Rent_per_Unit]]*12 -> 1340196 | AD2: =PortfolioData[[#This Row],[Potential_Revenue]]-PortfolioData[[#This Row],[Gross_Rental_Income]] -> 264264 | AE2: =IFERROR(PortfolioData[[#This Row],[Vacancy_Loss]]/PortfolioData[[#This Row],[Potential_Revenue]],0) -> 0.1971831 | AF2: =(PortfolioData[[#This Row],[Vacancy_%]] * 0.4) + (PortfolioData[[#This Row],[Debt_Ratio]] * 0.3) + (PortfolioData[[#This Row],[Interest_Rate]]/100 * 0.3) -> 0.86206334
A3: P143 | B3: Adelaide | C3: Mixed-use | D3: 2020 | E3: 5131150 | F3: 5251723.4 | G3: 57 | H3: 42 | I3: 4135 | J3: 453835 | K3: 438286 | L3: 12882576 | M3: 3.69 | N3: Long-term | O3: =PortfolioData[[#This Row],[Occupied_Units]]*PortfolioData[[#This Row],[Avg_Rent_per_Unit]]*12 -> 2084040 | P3: =1-(PortfolioData[[#This Row],[Occupied_Units]]/PortfolioData[[#This Row],[Units]]) -> 0.26315789 | Q3: =PortfolioData[[#This Row],[Gross_Rental_Income]] - PortfolioData[[#This Row],[Operating_Cost]] - PortfolioData[[#This Row],[Maintenance_Cost]] -> 1191919 | R3: =PortfolioData[[#This Row],[Adjusted_Debt_Outstanding]]*(PortfolioData[[#This Row],[Interest_Rate]]/100) -> 155030.88 | S3: =MIN(PortfolioData[[#This Row],[Debt_Outstanding]], PortfolioData[[#This Row],[Current_Value]]*0.8) -> 4201378.7 | T3: =PortfolioData[[#This Row],[Net Operating Income (NOI)]]/PortfolioData[[#This Row],[Annual_Debt_Service]] -> 7.6882685 | U3: =PortfolioData[[#This Row],[Net Operating Income (NOI)]]-PortfolioData[[#This Row],[Annual_Debt_Service]] -> 1036888.1 | V3: =PortfolioData[[#This Row],[Net Operating Income (NOI)]] -> 1191919 | W3: =PortfolioData[[#This Row],[Gross_Rental_Income]] / PortfolioData[[#This Row],[Purchase_Price]] -> 0.40615457 | X3: =PortfolioData[[#This Row],[Net Operating Income (NOI)]]/PortfolioData[[#This Row],[Current_Value]] -> 0.22695769 | Y3: =(PortfolioData[[#This Row],[Current_Value]]-PortfolioData[[#This Row],[Purchase_Price]]+PortfolioData[[#This Row],[Net Operating Income (NOI)]]) / PortfolioData[[#This Row],[Purchase_Price]] -> 0.25578913 | Z3: =_xlfn.PERCENTRANK.INC(PortfolioData[ROI],PortfolioData[[#This Row],[ROI]]) -> 0.57 | AA3: =IF(PortfolioData[[#This Row],[ROI_Percentile]]<=0.1,"Underperforming","Healthy") -> Healthy | AB3: =PortfolioData[[#This Row],[Debt_Outstanding]]/PortfolioData[[#This Row],[Current_Value]] -> 2.4530188 | AC3: =PortfolioData[[#This Row],[Units]]*PortfolioData[[#This Row],[Avg_Rent_per_Unit]]*12 -> 2828340 | AD3: =PortfolioData[[#This Row],[Potential_Revenue]]-PortfolioData[[#This Row],[Gross_Rental_Income]] -> 744300 | AE3: =IFERROR(PortfolioData[[#This Row],[Vacancy_Loss]]/PortfolioData[[#This Row],[Potential_Revenue]],0) -> 0.26315789 | AF3: =(PortfolioData[[#This Row],[Vacancy_%]] * 0.4) + (PortfolioData[[#This Row],[Debt_Ratio]] * 0.3) + (PortfolioData[[#This Row],[Interest_Rate]]/100 * 0.3) -> 0.85223878
A4: P100 | B4: Melbourne | C4: Retail | D4: 2016 | E4: 5300981 | F4: 5096846 | G4: 66 | H4: 46 | I4: 2414 | J4: 221485 | K4: 468962 | L4: 11028997 | M4: 4.57 | N4: Long-term | O4: =PortfolioData[[#This Row],[Occupied_Units]]*PortfolioData[[#This Row],[Avg_Rent_per_Unit]]*12 -> 1332528 | P4: =1-(PortfolioData[[#This Row],[Occupied_Units]]/PortfolioData[[#This Row],[Units]]) -> 0.3030303 | Q4: =PortfolioData[[#This Row],[Gross_Rental_Income]] - PortfolioData[[#This Row],[Operating_Cost]] - PortfolioData[[#This Row],[Maintenance_Cost]] -> 642081 | R4: =PortfolioData[[#This Row],[Adjusted_Debt_Outstanding]]*(PortfolioData[[#This Row],[Interest_Rate]]/100) -> 186340.69 | S4: =MIN(PortfolioData[[#This Row],[Debt_Outstanding]], PortfolioData[[#This Row],[Current_Value]]*0.8) -> 4077476.8 | T4: =PortfolioData[[#This Row],[Net Operating Income (NOI)]]/PortfolioData[[#This Row],[Annual_Debt_Service]] -> 3.445737 | U4: =PortfolioData[[#This Row],[Net Operating Income (NOI)]]-PortfolioData[[#This Row],[Annual_Debt_Service]] -> 455740.31 | V4: =PortfolioData[[#This Row],[Net Operating Income (NOI)]] -> 642081 | W4: =PortfolioData[[#This Row],[Gross_Rental_Income]] / PortfolioData[[#This Row],[Purchase_Price]] -> 0.25137385 | X4: =PortfolioData[[#This Row],[Net Operating Income (NOI)]]/PortfolioData[[#This Row],[Current_Value]] -> 0.12597614 | Y4: =(PortfolioData[[#This Row],[Current_Value]]-PortfolioData[[#This Row],[Purchase_Price]]+PortfolioData[[#This Row],[Net Operating Income (NOI)]]) / PortfolioData[[#This Row],[Purchase_Price]] -> 0.082616027 | Z4: =_xlfn.PERCENTRANK.INC(PortfolioData[ROI],PortfolioData[[#This Row],[ROI]]) -> 0.302 | AA4: =IF(PortfolioData[[#This Row],[ROI_Percentile]]<=0.1,"Underperforming","Healthy") -> Healthy | AB4: =PortfolioData[[#This Row],[Debt_Outstanding]]/PortfolioData[[#This Row],[Current_Value]] -> 2.1638867 | AC4: =PortfolioData[[#This Row],[Units]]*PortfolioData[[#This Row],[Avg_Rent_per_Unit]]*12 -> 1911888 | AD4: =PortfolioData[[#This Row],[Potential_Revenue]]-PortfolioData[[#This Row],[Gross_Rental_Income]] -> 579360 | AE4: =IFERROR(PortfolioData[[#This Row],[Vacancy_Loss]]/PortfolioData[[#This Row],[Potential_Revenue]],0) -> 0.3030303 | AF4: =(PortfolioData[[#This Row],[Vacancy_%]] * 0.4) + (PortfolioData[[#This Row],[Debt_Ratio]] * 0.3) + (PortfolioData[[#This Row],[Interest_Rate]]/100 * 0.3) -> 0.78408812
A5: P054 | B5: Adelaide | C5: Warehouse | D5: 2012 | E5: 7451126 | F5: 6882757.9 | G5: 33 | H5: 24 | I5: 2746 | J5: 505023 | K5: 311008 | L5: 14255329 | M5: 5.81 | N5: Long-term | O5: =PortfolioData[[#This Row],[Occupied_Units]]*PortfolioData[[#This Row],[Avg_Rent_per_Unit]]*12 -> 790848 | P5: =1-(PortfolioData[[#This Row],[Occupied_Units]]/PortfolioData[[#This Row],[Units]]) -> 0.27272727 | Q5: =PortfolioData[[#This Row],[Gross_Rental_Income]] - PortfolioData[[#This Row],[Operating_Cost]] - PortfolioData[[#This Row],[Maintenance_Cost]] -> -25183 | R5: =PortfolioData[[#This Row],[Adjusted_Debt_Outstanding]]*(PortfolioData[[#This Row],[Interest_Rate]]/100) -> 319910.59 | S5: =MIN(PortfolioData[[#This Row],[Debt_Outstanding]], PortfolioData[[#This Row],[Current_Value]]*0.8) -> 5506206.3 | T5: =PortfolioData[[#This Row],[Net Operating Income (NOI)]]/PortfolioData[[#This Row],[Annual_Debt_Service]] -> -0.07871887 | U5: =PortfolioData[[#This Row],[Net Operating Income (NOI)]]-PortfolioData[[#This Row],[Annual_Debt_Service]] -> -345093.59 | V5: =PortfolioData[[#This Row],[Net Operating Income (NOI)]] -> -25183 | W5: =PortfolioData[[#This Row],[Gross_Rental_Income]] / PortfolioData[[#This Row],[Purchase_Price]] -> 0.10613805 | X5: =PortfolioData[[#This Row],[Net Operating Income (NOI)]]/PortfolioData[[#This Row],[Current_Value]] -> -0.0036588531 | Y5: =(PortfolioData[[#This Row],[Current_Value]]-PortfolioData[[#This Row],[Purchase_Price]]+PortfolioData[[#This Row],[Net Operating Income (NOI)]]) / PortfolioData[[#This Row],[Purchase_Price]] -> -0.079659246 | Z5: =_xlfn.PERCENTRANK.INC(PortfolioData[ROI],PortfolioData[[#This Row],[ROI]]) -> 0.04 | AA5: =IF(PortfolioData[[#This Row],[ROI_Percentile]]<=0.1,"Underperforming","Healthy") -> Underperforming | AB5: =PortfolioData[[#This Row],[Debt_Outstanding]]/PortfolioData[[#This Row],[Current_Value]] -> 2.0711652 | AC5: =PortfolioData[[#This Row],[Units]]*PortfolioData[[#This Row],[Avg_Rent_per_Unit]]*12 -> 1087416 | AD5: =PortfolioData[[#This Row],[Potential_Revenue]]-PortfolioData[[#This Row],[Gross_Rental_Income]] -> 296568 | AE5: =IFERROR(PortfolioData[[#This Row],[Vacancy_Loss]]/PortfolioData[[#This Row],[Potential_Revenue]],0) -> 0.27272727 | AF5: =(PortfolioData[[#This Row],[Vacancy_%]] * 0.4) + (PortfolioData[[#This Row],[Debt_Ratio]] * 0.3) + (PortfolioData[[#This Row],[Interest_Rate]]/100 * 0.3) -> 0.74787048
A6: P082 | B6: Brisbane | C6: Mixed-use | D6: 2010 | E6: 5016882 | F6: 4520108.4 | G6: 43 | H6: 30 | I6: 2409 | J6: 491311 | K6: 142175 | L6: 7365453 | M6: 5.58 | N6: Long-term | O6: =PortfolioData[[#This Row],[Occupied_Units]]*PortfolioData[[#This Row],[Avg_Rent_per_Unit]]*12 -> 867240 | P6: =1-(PortfolioData[[#This Row],[Occupied_Units]]/PortfolioData[[#This Row],[Units]]) -> 0.30232558 | Q6: =PortfolioData[[#This Row],[Gross_Rental_Income]] - PortfolioData[[#This Row],[Operating_Cost]] - PortfolioData[[#This Row],[Maintenance_Cost]] -> 233754 | R6: =PortfolioData[[#This Row],[Adjusted_Debt_Outstanding]]*(PortfolioData[[#This Row],[Interest_Rate]]/100) -> 201777.64 | S6: =MIN(PortfolioData[[#This Row],[Debt_Outstanding]], PortfolioData[[#This Row],[Current_Value]]*0.8) -> 3616086.7 | T6: =PortfolioData[[#This Row],[Net Operating Income (NOI)]]/PortfolioData[[#This Row],[Annual_Debt_Service]] -> 1.1584733 | U6: =PortfolioData[[#This Row],[Net Operating Income (NOI)]]-PortfolioData[[#This Row],[Annual_Debt_Service]] -> 31976.362 | V6: =PortfolioData[[#This Row],[Net Operating Income (NOI)]] -> 233754 | W6: =PortfolioData[[#This Row],[Gross_Rental_Income]] / PortfolioData[[#This Row],[Purchase_Price]] -> 0.17286434 | X6: =PortfolioData[[#This Row],[Net Operating Income (NOI)]]/PortfolioData[[#This Row],[Current_Value]] -> 0.051714247 | Y6: =(PortfolioData[[#This Row],[Current_Value]]-PortfolioData[[#This Row],[Purchase_Price]]+PortfolioData[[#This Row],[Net Operating Income (NOI)]]) / PortfolioData[[#This Row],[Purchase_Price]] -> -0.05242691 | Z6: =_xlfn.PERCENTRANK.INC(PortfolioData[ROI],PortfolioData[[#This Row],[ROI]]) -> 0.06 | AA6: =IF(PortfolioData[[#This Row],[ROI_Percentile]]<=0.1,"Underperforming","Healthy") -> Underperforming | AB6: =PortfolioData[[#This Row],[Debt_Outstanding]]/PortfolioData[[#This Row],[Current_Value]] -> 1.6294859 | AC6: =PortfolioData[[#This Row],[Units]]*PortfolioData[[#This Row],[Avg_Rent_per_Unit]]*12 -> 1243044 | AD6: =PortfolioData[[#This Row],[Potential_Revenue]]-PortfolioData[[#This Row],[Gross_Rental_Income]] -> 375804 | AE6: =IFERROR(PortfolioData[[#This Row],[Vacancy_Loss]]/PortfolioData[[#This Row],[Potential_Revenue]],0) -> 0.30232558 | AF6: =(PortfolioData[[#This Row],[Vacancy_%]] * 0.4) + (PortfolioData[[#This Row],[Debt_Ratio]] * 0.3) + (PortfolioData[[#This Row],[Interest_Rate]]/100 * 0.3) -> 0.62651601
A7: P093 | B7: Sydney | C7: Retail | D7: 2016 | E7: 7933523 | F7: 8773658.2 | G7: 74 | H7: 55 | I7: 5525 | J7: 253604 | K7: 489093 | L7: 14782621 | M7: 5.08 | N7: Short-term | O7: =PortfolioData[[#This Row],[Occupied_Units]]*PortfolioData[[#This Row],[Avg_Rent_per_Unit]]*12 -> 3646500 | P7: =1-(PortfolioData[[#This Row],[Occupied_Units]]/PortfolioData[[#This Row],[Units]]) -> 0.25675676 | Q7: =PortfolioData[[#This Row],[Gross_Rental_Income]] - PortfolioData[[#This Row],[Operating_Cost]] - PortfolioData[[#This Row],[Maintenance_Cost]] -> 2903803 | R7: =PortfolioData[[#This Row],[Adjusted_Debt_Outstanding]]*(PortfolioData[[#This Row],[Interest_Rate]]/100) -> 356561.47 | S7: =MIN(PortfolioData[[#This Row],[Debt_Outstanding]], PortfolioData[[#This Row],[Current_Value]]*0.8) -> 7018926.5 | T7: =PortfolioData[[#This Row],[Net Operating Income (NOI)]]/PortfolioData[[#This Row],[Annual_Debt_Service]] -> 8.1439058 | U7: =PortfolioData[[#This Row],[Net Operating Income (NOI)]]-PortfolioData[[#This Row],[Annual_Debt_Service]] -> 2547241.5 | V7: =PortfolioData[[#This Row],[Net Operating Income (NOI)]] -> 2903803 | W7: =PortfolioData[[#This Row],[Gross_Rental_Income]] / PortfolioData[[#This Row],[Purchase_Price]] -> 0.45963187 | X7: =PortfolioData[[#This Row],[Net Operating Income (NOI)]]/PortfolioData[[#This Row],[Current_Value]] -> 0.33096833 | Y7: =(PortfolioData[[#This Row],[Current_Value]]-PortfolioData[[#This Row],[Purchase_Price]]+PortfolioData[[#This Row],[Net Operating Income (NOI)]]) / PortfolioData[[#This Row],[Purchase_Price]] -> 0.4719137 | Z7: =_xlfn.PERCENTRANK.INC(PortfolioData[ROI],PortfolioData[[#This Row],[ROI]]) -> 0.939 | AA7: =IF(PortfolioData[[#This Row],[ROI_Percentile]]<=0.1,"Underperforming","Healthy") -> Healthy | AB7: =PortfolioData[[#This Row],[Debt_Outstanding]]/PortfolioData[[#This Row],[Current_Value]] -> 1.6848868 | AC7: =PortfolioData[[#This Row],[Units]]*PortfolioData[[#This Row],[Avg_Rent_per_Unit]]*12 -> 4906200 | AD7: =PortfolioData[[#This Row],[Potential_Revenue]]-PortfolioData[[#This Row],[Gross_Rental_Income]] -> 1259700 | AE7: =IFERROR(PortfolioData[[#This Row],[Vacancy_Loss]]/PortfolioData[[#This Row],[Potential_Revenue]],0) -> 0.25675676 | AF7: =(PortfolioData[[#This Row],[Vacancy_%]] * 0.4) + (PortfolioData[[#This Row],[Debt_Ratio]] * 0.3) + (PortfolioData[[#This Row],[Interest_Rate]]/100 * 0.3) -> 0.62340875
A8: P028 | B8: Melbourne | C8: Warehouse | D8: 2013 | E8: 5218931 | F8: 6879819.4 | G8: 44 | H8: 36 | I8: 2992 | J8: 704637 | K8: 487215 | L8: 11562019 | M8: 6.91 | N8: Short-term | O8: =PortfolioData[[#This Row],[Occupied_Units]]*PortfolioData[[#This Row],[Avg_Rent_per_Unit]]*12 -> 1292544 | P8: =1-(PortfolioData[[#This Row],[Occupied_Units]]/PortfolioData[[#This Row],[Units]]) -> 0.18181818 | Q8: =PortfolioData[[#This Row],[Gross_Rental_Income]] - PortfolioData[[#This Row],[Operating_Cost]] - PortfolioData[[#This Row],[Maintenance_Cost]] -> 100692 | R8: =PortfolioData[[#This Row],[Adjusted_Debt_Outstanding]]*(PortfolioData[[#This Row],[Interest_Rate]]/100) -> 380316.42 | S8: =MIN(PortfolioData[[#This Row],[Debt_Outstanding]], PortfolioData[[#This Row],[Current_Value]]*0.8) -> 5503855.5 | T8: =PortfolioData[[#This Row],[Net Operating Income (NOI)]]/PortfolioData[[#This Row],[Annual_Debt_Service]] -> 0.26475849 | U8: =PortfolioData[[#This Row],[Net Operating Income (NOI)]]-PortfolioData[[#This Row],[Annual_Debt_Service]] -> -279624.42 | V8: =PortfolioData[[#This Row],[Net Operating Income (NOI)]] -> 100692 | W8: =PortfolioData[[#This Row],[Gross_Rental_Income]] / PortfolioData[[#This Row],[Purchase_Price]] -> 0.24766451 | X8: =PortfolioData[[#This Row],[Net Operating Income (NOI)]]/PortfolioData[[#This Row],[Current_Value]] -> 0.014635849 | Y8: =(PortfolioData[[#This Row],[Current_Value]]-PortfolioData[[#This Row],[Purchase_Price]]+PortfolioData[[#This Row],[Net Operating Income (NOI)]]) / PortfolioData[[#This Row],[Purchase_Price]] -> 0.33753664 | Z8: =_xlfn.PERCENTRANK.INC(PortfolioData[ROI],PortfolioData[[#This Row],[ROI]]) -> 0.758 | AA8: =IF(PortfolioData[[#This Row],[ROI_Percentile]]<=0.1,"Underperforming","Healthy") -> Healthy | AB8: =PortfolioData[[#This Row],[Debt_Outstanding]]/PortfolioData[[#This Row],[Current_Value]] -> 1.6805701 | AC8: =PortfolioData[[#This Row],[Units]]*PortfolioData[[#This Row],[Avg_Rent_per_Unit]]*12 -> 1579776 | AD8: =PortfolioData[[#This Row],[Potential_Revenue]]-PortfolioData[[#This Row],[Gross_Rental_Income]] -> 287232 | AE8: =IFERROR(PortfolioData[[#This Row],[Vacancy_Loss]]/PortfolioData[[#This Row],[Potential_Revenue]],0) -> 0.18181818 | AF8: =(PortfolioData[[#This Row],[Vacancy_%]] * 0.4) + (PortfolioData[[#This Row],[Debt_Ratio]] * 0.3) + (PortfolioData[[#This Row],[Interest_Rate]]/100 * 0.3) -> 0.59762831
A9: P142 | B9: Melbourne | C9: Warehouse | D9: 2016 | E9: 5969384 | F9: 8314584.7 | G9: 10 | H9: 7 | I9: 3228 | J9: 775923 | K9: 106926 | L9: 12471358 | M9: 6.64 | N9: Long-term | O9: =PortfolioData[[#This Row],[Occupied_Units]]*PortfolioData[[#This Row],[Avg_Rent_per_Unit]]*12 -> 271152 | P9: =1-(PortfolioData[[#This Row],[Occupied_Units]]/PortfolioData[[#This Row],[Units]]) -> 0.3 | Q9: =PortfolioData[[#This Row],[Gross_Rental_Income]] - PortfolioData[[#This Row],[Operating_Cost]] - PortfolioData[[#This Row],[Maintenance_Cost]] -> -611697 | R9: =PortfolioData[[#This Row],[Adjusted_Debt_Outstanding]]*(PortfolioData[[#This Row],[Interest_Rate]]/100) -> 441670.74 | S9: =MIN(PortfolioData[[#This Row],[Debt_Outstanding]], PortfolioData[[#This Row],[Current_Value]]*0.8) -> 6651667.8 | T9: =PortfolioData[[#This Row],[Net Operating Income (NOI)]]/PortfolioData[[#This Row],[Annual_Debt_Service]] -> -1.3849616 | U9: =PortfolioData[[#This Row],[Net Operating Income (NOI)]]-PortfolioData[[#This Row],[Annual_Debt_Service]] -> -1053367.7 | V9: =PortfolioData[[#This Row],[Net Operating Income (NOI)]] -> -611697 | W9: =PortfolioData[[#This Row],[Gross_Rental_Income]] / PortfolioData[[#This Row],[Purchase_Price]] -> 0.045423782 | X9: =PortfolioData[[#This Row],[Net Operating Income (NOI)]]/PortfolioData[[#This Row],[Current_Value]] -> -0.073569158 | Y9: =(PortfolioData[[#This Row],[Current_Value]]-PortfolioData[[#This Row],[Purchase_Price]]+PortfolioData[[#This Row],[Net Operating Income (NOI)]]) / PortfolioData[[#This Row],[Purchase_Price]] -> 0.2903991 | Z9: =_xlfn.PERCENTRANK.INC(PortfolioData[ROI],PortfolioData[[#This Row],[ROI]]) -> 0.664 | AA9: =IF(PortfolioData[[#This Row],[ROI_Percentile]]<=0.1,"Underperforming","Healthy") -> Healthy | AB9: =PortfolioData[[#This Row],[Debt_Outstanding]]/PortfolioData[[#This Row],[Current_Value]] -> 1.4999376 | AC9: =PortfolioData[[#This Row],[Units]]*PortfolioData[[#This Row],[Avg_Rent_per_Unit]]*12 -> 387360 | AD9: =PortfolioData[[#This Row],[Potential_Revenue]]-PortfolioData[[#This Row],[Gross_Rental_Income]] -> 116208 | AE9: =IFERROR(PortfolioData[[#This Row],[Vacancy_Loss]]/PortfolioData[[#This Row],[Potential_Revenue]],0) -> 0.3 | AF9: =(PortfolioData[[#This Row],[Vacancy_%]] * 0.4) + (PortfolioData[[#This Row],[Debt_Ratio]] * 0.3) + (PortfolioData[[#This Row],[Interest_Rate]]/100 * 0.3) -> 0.58990127
A10: P061 | B10: Melbourne | C10: Office | D10: 2019 | E10: 7493243 | F10: 7321306.3 | G10: 41 | H10: 40 | I10: 2629 | J10: 603713 | K10: 477947 | L10: 13691119 | M10: 4.1 | N10: Long-term | O10: =PortfolioData[[#This Row],[Occupied_Units]]*PortfolioData[[#This Row],[Avg_Rent_per_Unit]]*12 -> 1261920 | P10: =1-(PortfolioData[[#This Row],[Occupied_Units]]/PortfolioData[[#This Row],[Units]]) -> 0.024390244 | Q10: =PortfolioData[[#This Row],[Gross_Rental_Income]] - PortfolioData[[#This Row],[Operating_Cost]] - PortfolioData[[#This Row],[Maintenance_Cost]] -> 180260 | R10: =PortfolioData[[#This Row],[Adjusted_Debt_Outstanding]]*(PortfolioData[[#This Row],[Interest_Rate]]/100) -> 240138.85 | S10: =MIN(PortfolioData[[#This Row],[Debt_Outstanding]], PortfolioData[[#This Row],[Current_Value]]*0.8) -> 5857045 | T10: =PortfolioData[[#This Row],[Net Operating Income (NOI)]]/PortfolioData[[#This Row],[Annual_Debt_Service]] -> 0.75064906 | U10: =PortfolioData[[#This Row],[Net Operating Income (NOI)]]-PortfolioData[[#This Row],[Annual_Debt_Service]] -> -59878.847 | V10: =PortfolioData[[#This Row],[Net Operating Income (NOI)]] -> 180260 | W10: =PortfolioData[[#This Row],[Gross_Rental_Income]] / PortfolioData[[#This Row],[Purchase_Price]] -> 0.16840772 | X10: =PortfolioData[[#This Row],[Net Operating Income (NOI)]]/PortfolioData[[#This Row],[Current_Value]] -> 0.024621289 | Y10: =(PortfolioData[[#This Row],[Current_Value]]-PortfolioData[[#This Row],[Purchase_Price]]+PortfolioData[[#This Row],[Net Operating Income (NOI)]]) / PortfolioData[[#This Row],[Purchase_Price]] -> 0.0011107754 | Z10: =_xlfn.PERCENTRANK.INC(PortfolioData[ROI],PortfolioData[[#This Row],[ROI]]) -> 0.154 | AA10: =IF(PortfolioData[[#This Row],[ROI_Percentile]]<=0.1,"Underperforming","Healthy") -> Healthy | AB10: =PortfolioData[[#This Row],[Debt_Outstanding]]/PortfolioData[[#This Row],[Current_Value]] -> 1.8700377 | AC10: =PortfolioData[[#This Row],[Units]]*PortfolioData[[#This Row],[Avg_Rent_per_Unit]]*12 -> 1293468 | AD10: =PortfolioData[[#This Row],[Potential_Revenue]]-PortfolioData[[#This Row],[Gross_Rental_Income]] -> 31548 | AE10: =IFERROR(PortfolioData[[#This Row],[Vacancy_Loss]]/PortfolioData[[#This Row],[Potential_Revenue]],0) -> 0.024390244 | AF10: =(PortfolioData[[#This Row],[Vacancy_%]] * 0.4) + (PortfolioData[[#This Row],[Debt_Ratio]] * 0.3) + (PortfolioData[[#This Row],[Interest_Rate]]/100 * 0.3) -> 0.58306742
A11: P010 | B11: Sydney | C11: Retail | D11: 2016 | E11: 6472531 | F11: 8046324.8 | G11: 31 | H11: 22 | I11: 5558 | J11: 563244 | K11: 434211 | L11: 12224206 | M11: 3.54 | N11: Long-term | O11: =PortfolioData[[#This Row],[Occupied_Units]]*PortfolioData[[#This Row],[Avg_Rent_per_Unit]]*12 -> 1467312 | P11: =1-(PortfolioData[[#This Row],[Occupied_Units]]/PortfolioData[[#This Row],[Units]]) -> 0.29032258 | Q11: =PortfolioData[[#This Row],[Gross_Rental_Income]] - PortfolioData[[#This Row],[Operating_Cost]] - PortfolioData[[#This Row],[Maintenance_Cost]] -> 469857 | R11: =PortfolioData[[#This Row],[Adjusted_Debt_Outstanding]]*(PortfolioData[[#This Row],[Interest_Rate]]/100) -> 227871.92 | S11: =MIN(PortfolioData[[#This Row],[Debt_Outstanding]], PortfolioData[[#This Row],[Current_Value]]*0.8) -> 6437059.9 | T11: =PortfolioData[[#This Row],[Net Operating Income (NOI)]]/PortfolioData[[#This Row],[Annual_Debt_Service]] -> 2.0619346 | U11: =PortfolioData[[#This Row],[Net Operating Income (NOI)]]-PortfolioData[[#This Row],[Annual_Debt_Service]] -> 241985.08 | V11: =PortfolioData[[#This Row],[Net Operating Income (NOI)]] -> 469857 | W11: =PortfolioData[[#This Row],[Gross_Rental_Income]] / PortfolioData[[#This Row],[Purchase_Price]] -> 0.22669833 | X11: =PortfolioData[[#This Row],[Net Operating Income (NOI)]]/PortfolioData[[#This Row],[Current_Value]] -> 0.058393989 | Y11: =(PortfolioData[[#This Row],[Current_Value]]-PortfolioData[[#This Row],[Purchase_Price]]+PortfolioData[[#This Row],[Net Operating Income (NOI)]]) / PortfolioData[[#This Row],[Purchase_Price]] -> 0.31574214 | Z11: =_xlfn.PERCENTRANK.INC(PortfolioData[ROI],PortfolioData[[#This Row],[ROI]]) -> 0.704 | AA11: =IF(PortfolioData[[#This Row],[ROI_Percentile]]<=0.1,"Underperforming","Healthy") -> Healthy | AB11: =PortfolioData[[#This Row],[Debt_Outstanding]]/PortfolioData[[#This Row],[Current_Value]] -> 1.5192285 | AC11: =PortfolioData[[#This Row],[Units]]*PortfolioData[[#This Row],[Avg_Rent_per_Unit]]*12 -> 2067576 | AD11: =PortfolioData[[#This Row],[Potential_Revenue]]-PortfolioData[[#This Row],[Gross_Rental_Income]] -> 600264 | AE11: =IFERROR(PortfolioData[[#This Row],[Vacancy_Loss]]/PortfolioData[[#This Row],[Potential_Revenue]],0) -> 0.29032258 | AF11: =(PortfolioData[[#This Row],[Vacancy_%]] * 0.4) + (PortfolioData[[#This Row],[Debt_Ratio]] * 0.3) + (PortfolioData[[#This Row],[Interest_Rate]]/100 * 0.3) -> 0.58251758
A12: P022 | B12: Perth | C12: Warehouse | D12: 2015 | E12: 8326702 | F12: 7881192.7 | G12: 10 | H12: 10 | I12: 5296 | J12: 679261 | K12: 235160 | L12: 14873961 | M12: 4.39 | N12: Long-term | O12: =PortfolioData[[#This Row],[Occupied_Units]]*PortfolioData[[#This Row],[Avg_Rent_per_Unit]]*12 -> 635520 | P12: =1-(PortfolioData[[#This Row],[Occupied_Units]]/PortfolioData[[#This Row],[Units]]) -> 0 | Q12: =PortfolioData[[#This Row],[Gross_Rental_Income]] - PortfolioData[[#This Row],[Operating_Cost]] - PortfolioData[[#This Row],[Maintenance_Cost]] -> -278901 | R12: =PortfolioData[[#This Row],[Adjusted_Debt_Outstanding]]*(PortfolioData[[#This Row],[Interest_Rate]]/100) -> 276787.49 | S12: =MIN(PortfolioData[[#This Row],[Debt_Outstanding]], PortfolioData[[#This Row],[Current_Value]]*0.8) -> 6304954.1 | T12: =PortfolioData[[#This Row],[Net Operating Income (NOI)]]/PortfolioData[[#This Row],[Annual_Debt_Service]] -> -1.0076359 | U12: =PortfolioData[[#This Row],[Net Operating Income (NOI)]]-PortfolioData[[#This Row],[Annual_Debt_Service]] -> -555688.49 | V12: =PortfolioData[[#This Row],[Net Operating Income (NOI)]] -> -278901 | W12: =PortfolioData[[#This Row],[Gross_Rental_Income]] / PortfolioData[[#This Row],[Purchase_Price]] -> 0.076323135 | X12: =PortfolioData[[#This Row],[Net Operating Income (NOI)]]/PortfolioData[[#This Row],[Current_Value]] -> -0.035388172 | Y12: =(PortfolioData[[#This Row],[Current_Value]]-PortfolioData[[#This Row],[Purchase_Price]]+PortfolioData[[#This Row],[Net Operating Income (NOI)]]) / PortfolioData[[#This Row],[Purchase_Price]] -> -0.086998471 | Z12: =_xlfn.PERCENTRANK.INC(PortfolioData[ROI],PortfolioData[[#This Row],[ROI]]) -> 0.026 | AA12: =IF(PortfolioData[[#This Row],[ROI_Percentile]]<=0.1,"Underperforming","Healthy") -> Underperforming | AB12: =PortfolioData[[#This Row],[Debt_Outstanding]]/PortfolioData[[#This Row],[Current_Value]] -> 1.8872729 | AC12: =PortfolioData[[#This Row],[Units]]*PortfolioData[[#This Row],[Avg_Rent_per_Unit]]*12 -> 635520 | AD12: =PortfolioData[[#This Row],[Potential_Revenue]]-PortfolioData[[#This Row],[Gross_Rental_Income]] -> 0 | AE12: =IFERROR(PortfolioData[[#This Row],[Vacancy_Loss]]/PortfolioData[[#This Row],[Potential_Revenue]],0) -> 0 | AF12: =(PortfolioData[[#This Row],[Vacancy_%]] * 0.4) + (PortfolioData[[#This Row],[Debt_Ratio]] * 0.3) + (PortfolioData[[#This Row],[Interest_Rate]]/100 * 0.3) -> 0.57935186
A13: P123 | B13: Sydney | C13: Warehouse | D13: 2011 | E13: 5814811 | F13: 7386393 | G13: 51 | H13: 40 | I13: 2447 | J13: 212595 | K13: 208207 | L13: 10846421 | M13: 5.84 | N13: Long-term | O13: =PortfolioData[[#This Row],[Occupied_Units]]*PortfolioData[[#This Row],[Avg_Rent_per_Unit]]*12 -> 1174560 | P13: =1-(PortfolioData[[#This Row],[Occupied_Units]]/PortfolioData[[#This Row],[Units]]) -> 0.21568627 | Q13: =PortfolioData[[#This Row],[Gross_Rental_Income]] - PortfolioData[[#This Row],[Operating_Cost]] - PortfolioData[[#This Row],[Maintenance_Cost]] -> 753758 | R13: =PortfolioData[[#This Row],[Adjusted_Debt_Outstanding]]*(PortfolioData[[#This Row],[Interest_Rate]]/100) -> 345092.28 | S13: =MIN(PortfolioData[[#This Row],[Debt_Outstanding]], PortfolioData[[#This Row],[Current_Value]]*0.8) -> 5909114.4 | T13: =PortfolioData[[#This Row],[Net Operating Income (NOI)]]/PortfolioData[[#This Row],[Annual_Debt_Service]] -> 2.1842215 | U13: =PortfolioData[[#This Row],[Net Operating Income (NOI)]]-PortfolioData[[#This Row],[Annual_Debt_Service]] -> 408665.72 | V13: =PortfolioData[[#This Row],[Net Operating Income (NOI)]] -> 753758 | W13: =PortfolioData[[#This Row],[Gross_Rental_Income]] / PortfolioData[[#This Row],[Purchase_Price]] -> 0.20199453 | X13: =PortfolioData[[#This Row],[Net Operating Income (NOI)]]/PortfolioData[[#This Row],[Current_Value]] -> 0.10204683 | Y13: =(PortfolioData[[#This Row],[Current_Value]]-PortfolioData[[#This Row],[Purchase_Price]]+PortfolioData[[#This Row],[Net Operating Income (NOI)]]) / PortfolioData[[#This Row],[Purchase_Price]] -> 0.39989951 | Z13: =_xlfn.PERCENTRANK.INC(PortfolioData[ROI],PortfolioData[[#This Row],[ROI]]) -> 0.859 | AA13: =IF(PortfolioData[[#This Row],[ROI_Percentile]]<=0.1,"Underperforming","Healthy") -> Healthy | AB13: =PortfolioData[[#This Row],[Debt_Outstanding]]/PortfolioData[[#This Row],[Current_Value]] -> 1.4684327 | AC13: =PortfolioData[[#This Row],[Units]]*PortfolioData[[#This Row],[Avg_Rent_per_Unit]]*12 -> 1497564 | AD13: =PortfolioData[[#This Row],[Potential_Revenue]]-PortfolioData[[#This Row],[Gross_Rental_Income]] -> 323004 | AE13: =IFERROR(PortfolioData[[#This Row],[Vacancy_Loss]]/PortfolioData[[#This Row],[Potential_Revenue]],0) -> 0.21568627 | AF13: =(PortfolioData[[#This Row],[Vacancy_%]] * 0.4) + (PortfolioData[[#This Row],[Debt_Ratio]] * 0.3) + (PortfolioData[[#This Row],[Interest_Rate]]/100 * 0.3) -> 0.54432432
A14: P025 | B14: Brisbane | C14: Warehouse | D14: 2014 | E14: 5073915 | F14: 4688062.3 | G14: 42 | H14: 34 | I14: 1708 | J14: 781549 | K14: 149380 | L14: 6612437 | M14: 6.12 | N14: Long-term | O14: =PortfolioData[[#This Row],[Occupied_Units]]*PortfolioData[[#This Row],[Avg_Rent_per_Unit]]*12 -> 696864 | P14: =1-(PortfolioData[[#This Row],[Occupied_Units]]/PortfolioData[[#This Row],[Units]]) -> 0.19047619 | Q14: =PortfolioData[[#This Row],[Gross_Rental_Income]] - PortfolioData[[#This Row],[Operating_Cost]] - PortfolioData[[#This Row],[Maintenance_Cost]] -> -234065 | R14: =PortfolioData[[#This Row],[Adjusted_Debt_Outstanding]]*(PortfolioData[[#This Row],[Interest_Rate]]/100) -> 229527.53 | S14: =MIN(PortfolioData[[#This Row],[Debt_Outstanding]], PortfolioData[[#This Row],[Current_Value]]*0.8) -> 3750449.8 | T14: =PortfolioData[[#This Row],[Net Operating Income (NOI)]]/PortfolioData[[#This Row],[Annual_Debt_Service]] -> -1.0197687 | U14: =PortfolioData[[#This Row],[Net Operating Income (NOI)]]-PortfolioData[[#This Row],[Annual_Debt_Service]] -> -463592.53 | V14: =PortfolioData[[#This Row],[Net Operating Income (NOI)]] -> -234065 | W14: =PortfolioData[[#This Row],[Gross_Rental_Income]] / PortfolioData[[#This Row],[Purchase_Price]] -> 0.13734247 | X14: =PortfolioData[[#This Row],[Net Operating Income (NOI)]]/PortfolioData[[#This Row],[Current_Value]] -> -0.049927877 | Y14: =(PortfolioData[[#This Row],[Current_Value]]-PortfolioData[[#This Row],[Purchase_Price]]+PortfolioData[[#This Row],[Net Operating Income (NOI)]]) / PortfolioData[[#This Row],[Purchase_Price]] -> -0.12217739 | Z14: =_xlfn.PERCENTRANK.INC(PortfolioData[ROI],PortfolioData[[#This Row],[ROI]]) -> 0 | AA14: =IF(PortfolioData[[#This Row],[ROI_Percentile]]<=0.1,"Underperforming","Healthy") -> Underperforming | AB14: =PortfolioData[[#This Row],[Debt_Outstanding]]/PortfolioData[[#This Row],[Current_Value]] -> 1.410484 | AC14: =PortfolioData[[#This Row],[Units]]*PortfolioData[[#This Row],[Avg_Rent_per_Unit]]*12 -> 860832 | AD14: =PortfolioData[[#This Row],[Potential_Revenue]]-PortfolioData[[#This Row],[Gross_Rental_Income]] -> 163968 | AE14: =IFERROR(PortfolioData[[#This Row],[Vacancy_Loss]]/PortfolioData[[#This Row],[Potential_Revenue]],0) -> 0.19047619 | AF14: =(PortfolioData[[#This Row],[Vacancy_%]] * 0.4) + (PortfolioData[[#This Row],[Debt_Ratio]] * 0.3) + (PortfolioData[[#This Row],[Interest_Rate]]/100 * 0.3) -> 0.51769568
A15: P079 | B15: Adelaide | C15: Retail | D15: 2016 | E15: 7711163 | F15: 8943715 | G15: 20 | H15: 14 | I15: 4519 | J15: 448101 | K15: 407818 | L15: 11004789 | M15: 6.54 | N15: Long-term | O15: =PortfolioData[[#This Row],[Occupied_Units]]*PortfolioData[[#This Row],[Avg_Rent_per_Unit]]*12 -> 759192 | P15: =1-(PortfolioData[[#This Row],[Occupied_Units]]/PortfolioData[[#This Row],[Units]]) -> 0.3 | Q15: =PortfolioData[[#This Row],[Gross_Rental_Income]] - PortfolioData[[#This Row],[Operating_Cost]] - PortfolioData[[#This Row],[Maintenance_Cost]] -> -96727 | R15: =PortfolioData[[#This Row],[Adjusted_Debt_Outstanding]]*(PortfolioData[[#This Row],[Interest_Rate]]/100) -> 467935.17 | S15: =MIN(PortfolioData[[#This Row],[Debt_Outstanding]], PortfolioData[[#This Row],[Current_Value]]*0.8) -> 7154972 | T15: =PortfolioData[[#This Row],[Net Operating Income (NOI)]]/PortfolioData[[#This Row],[Annual_Debt_Service]] -> -0.20671026 | U15: =PortfolioData[[#This Row],[Net Operating Income (NOI)]]-PortfolioData[[#This Row],[Annual_Debt_Service]] -> -564662.17 | V15: =PortfolioData[[#This Row],[Net Operating Income (NOI)]] -> -96727 | W15: =PortfolioData[[#This Row],[Gross_Rental_Income]] / PortfolioData[[#This Row],[Purchase_Price]] -> 0.098453631 | X15: =PortfolioData[[#This Row],[Net Operating Income (NOI)]]/PortfolioData[[#This Row],[Current_Value]] -> -0.010815081 | Y15: =(PortfolioData[[#This Row],[Current_Value]]-PortfolioData[[#This Row],[Purchase_Price]]+PortfolioData[[#This Row],[Net Operating Income (NOI)]]) / PortfolioData[[#This Row],[Purchase_Price]] -> 0.1472962 | Z15: =_xlfn.PERCENTRANK.INC(PortfolioData[ROI],PortfolioData[[#This Row],[ROI]]) -> 0.375 | AA15: =IF(PortfolioData[[#This Row],[ROI_Percentile]]<=0.1,"Underperforming","Healthy") -> Healthy | AB15: =PortfolioData[[#This Row],[Debt_Outstanding]]/PortfolioData[[#This Row],[Current_Value]] -> 1.2304494 | AC15: =PortfolioData[[#This Row],[Units]]*PortfolioData[[#This Row],[Avg_Rent_per_Unit]]*12 -> 1084560 | AD15: =PortfolioData[[#This Row],[Potential_Revenue]]-PortfolioData[[#This Row],[Gross_Rental_Income]] -> 325368 | AE15: =IFERROR(PortfolioData[[#This Row],[Vacancy_Loss]]/PortfolioData[[#This Row],[Potential_Revenue]],0) -> 0.3 | AF15: =(PortfolioData[[#This Row],[Vacancy_%]] * 0.4) + (PortfolioData[[#This Row],[Debt_Ratio]] * 0.3) + (PortfolioData[[#This Row],[Interest_Rate]]/100 * 0.3) -> 0.50875483 | AH15: =AVERAGE(AF3:AF151) -> 0.26201602
A16: P129 | B16: Sydney | C16: Mixed-use | D16: 2016 | E16: 9069514 | F16: 11499496 | G16: 14 | H16: 9 | I16: 5516 | J16: 407235 | K16: 133639 | L16: 12757058 | M16: 4.22 | N16: Short-term | O16: =PortfolioData[[#This Row],[Occupied_Units]]*PortfolioData[[#This Row],[Avg_Rent_per_Unit]]*12 -> 595728 | P16: =1-(PortfolioData[[#This Row],[Occupied_Units]]/PortfolioData[[#This Row],[Units]]) -> 0.35714286 | Q16: =PortfolioData[[#This Row],[Gross_Rental_Income]] - PortfolioData[[#This Row],[Operating_Cost]] - PortfolioData[[#This Row],[Maintenance_Cost]] -> 54854 | R16: =PortfolioData[[#This Row],[Adjusted_Debt_Outstanding]]*(PortfolioData[[#This Row],[Interest_Rate]]/100) -> 388222.98 | S16: =MIN(PortfolioData[[#This Row],[Debt_Outstanding]], PortfolioData[[#This Row],[Current_Value]]*0.8) -> 9199596.7 | T16: =PortfolioData[[#This Row],[Net Operating Income (NOI)]]/PortfolioData[[#This Row],[Annual_Debt_Service]] -> 0.14129509 | U16: =PortfolioData[[#This Row],[Net Operating Income (NOI)]]-PortfolioData[[#This Row],[Annual_Debt_Service]] -> -333368.98 | V16: =PortfolioData[[#This Row],[Net Operating Income (NOI)]] -> 54854 | W16: =PortfolioData[[#This Row],[Gross_Rental_Income]] / PortfolioData[[#This Row],[Purchase_Price]] -> 0.065684666 | X16: =PortfolioData[[#This Row],[Net Operating Income (NOI)]]/PortfolioData[[#This Row],[Current_Value]] -> 0.0047701222 | Y16: =(PortfolioData[[#This Row],[Current_Value]]-PortfolioData[[#This Row],[Purchase_Price]]+PortfolioData[[#This Row],[Net Operating Income (NOI)]]) / PortfolioData[[#This Row],[Purchase_Price]] -> 0.27397674 | Z16: =_xlfn.PERCENTRANK.INC(PortfolioData[ROI],PortfolioData[[#This Row],[ROI]]) -> 0.61 | AA16: =IF(PortfolioData[[#This Row],[ROI_Percentile]]<=0.1,"Underperforming","Healthy") -> Healthy | AB16: =PortfolioData[[#This Row],[Debt_Outstanding]]/PortfolioData[[#This Row],[Current_Value]] -> 1.109358 | AC16: =PortfolioData[[#This Row],[Units]]*PortfolioData[[#This Row],[Avg_Rent_per_Unit]]*12 -> 926688 | AD16: =PortfolioData[[#This Row],[Potential_Revenue]]-PortfolioData[[#This Row],[Gross_Rental_Income]] -> 330960 | AE16: =IFERROR(PortfolioData[[#This Row],[Vacancy_Loss]]/PortfolioData[[#This Row],[Potential_Revenue]],0) -> 0.35714286 | AF16: =(PortfolioData[[#This Row],[Vacancy_%]] * 0.4) + (PortfolioData[[#This Row],[Debt_Ratio]] * 0.3) + (PortfolioData[[#This Row],[Interest_Rate]]/100 * 0.3) -> 0.48832455
A17: P149 | B17: Perth | C17: Warehouse | D17: 2018 | E17: 6398924 | F17: 8941674.2 | G17: 49 | H17: 34 | I17: 4433 | J17: 488273 | K17: 259540 | L17: 9832692 | M17: 3.89 | N17: Long-term | O17: =PortfolioData[[#This Row],[Occupied_Units]]*PortfolioData[[#This Row],[Avg_Rent_per_Unit]]*12 -> 1808664 | P17: =1-(PortfolioData[[#This Row],[Occupied_Units]]/PortfolioData[[#This Row],[Units]]) -> 0.30612245 | Q17: =PortfolioData[[#This Row],[Gross_Rental_Income]] - PortfolioData[[#This Row],[Operating_Cost]] - PortfolioData[[#This Row],[Maintenance_Cost]] -> 1060851 | R17: =PortfolioData[[#This Row],[Adjusted_Debt_Outstanding]]*(PortfolioData[[#This Row],[Interest_Rate]]/100) -> 278264.9 | S17: =MIN(PortfolioData[[#This Row],[Debt_Outstanding]], PortfolioData[[#This Row],[Current_Value]]*0.8) -> 7153339.4 | T17: =PortfolioData[[#This Row],[Net Operating Income (NOI)]]/PortfolioData[[#This Row],[Annual_Debt_Service]] -> 3.812378 | U17: =PortfolioData[[#This Row],[Net Operating Income (NOI)]]-PortfolioData[[#This Row],[Annual_Debt_Service]] -> 782586.1 | V17: =PortfolioData[[#This Row],[Net Operating Income (NOI)]] -> 1060851 | W17: =PortfolioData[[#This Row],[Gross_Rental_Income]] / PortfolioData[[#This Row],[Purchase_Price]] -> 0.28265127 | X17: =PortfolioData[[#This Row],[Net Operating Income (NOI)]]/PortfolioData[[#This Row],[Current_Value]] -> 0.1186412 | Y17: =(PortfolioData[[#This Row],[Current_Value]]-PortfolioData[[#This Row],[Purchase_Price]]+PortfolioData[[#This Row],[Net Operating Income (NOI)]]) / PortfolioData[[#This Row],[Purchase_Price]] -> 0.56315737 | Z17: =_xlfn.PERCENTRANK.INC(PortfolioData[ROI],PortfolioData[[#This Row],[ROI]]) -> 0.979 | AA17: =IF(PortfolioData[[#This Row],[ROI_Percentile]]<=0.1,"Underperforming","Healthy") -> Healthy | AB17: =PortfolioData[[#This Row],[Debt_Outstanding]]/PortfolioData[[#This Row],[Current_Value]] -> 1.0996478 | AC17: =PortfolioData[[#This Row],[Units]]*PortfolioData[[#This Row],[Avg_Rent_per_Unit]]*12 -> 2606604 | AD17: =PortfolioData[[#This Row],[Potential_Revenue]]-PortfolioData[[#This Row],[Gross_Rental_Income]] -> 797940 | AE17: =IFERROR(PortfolioData[[#This Row],[Vacancy_Loss]]/PortfolioData[[#This Row],[Potential_Revenue]],0) -> 0.30612245 | AF17: =(PortfolioData[[#This Row],[Vacancy_%]] * 0.4) + (PortfolioData[[#This Row],[Debt_Ratio]] * 0.3) + (PortfolioData[[#This Row],[Interest_Rate]]/100 * 0.3) -> 0.46401331
A18: P043 | B18: Melbourne | C18: Retail | D18: 2014 | E18: 10199496 | F18: 12006385 | G18: 31 | H18: 21 | I18: 5842 | J18: 799466 | K18: 206290 | L18: 12755090 | M18: 5.35 | N18: Long-term | O18: =PortfolioData[[#This Row],[Occupied_Units]]*PortfolioData[[#This Row],[Avg_Rent_per_Unit]]*12 -> 1472184 | P18: =1-(PortfolioData[[#This Row],[Occupied_Units]]/PortfolioData[[#This Row],[Units]]) -> 0.32258065 | Q18: =PortfolioData[[#This Row],[Gross_Rental_Income]] - PortfolioData[[#This Row],[Operating_Cost]] - PortfolioData[[#This Row],[Maintenance_Cost]] -> 466428 | R18: =PortfolioData[[#This Row],[Adjusted_Debt_Outstanding]]*(PortfolioData[[#This Row],[Interest_Rate]]/100) -> 513873.27 | S18: =MIN(PortfolioData[[#This Row],[Debt_Outstanding]], PortfolioData[[#This Row],[Current_Value]]*0.8) -> 9605107.8 | T18: =PortfolioData[[#This Row],[Net Operating Income (NOI)]]/PortfolioData[[#This Row],[Annual_Debt_Service]] -> 0.90767127 | U18: =PortfolioData[[#This Row],[Net Operating Income (NOI)]]-PortfolioData[[#This Row],[Annual_Debt_Service]] -> -47445.266 | V18: =PortfolioData[[#This Row],[Net Operating Income (NOI)]] -> 466428 | W18: =PortfolioData[[#This Row],[Gross_Rental_Income]] / PortfolioData[[#This Row],[Purchase_Price]] -> 0.1443389 | X18: =PortfolioData[[#This Row],[Net Operating Income (NOI)]]/PortfolioData[[#This Row],[Current_Value]] -> 0.03884833 | Y18: =(PortfolioData[[#This Row],[Current_Value]]-PortfolioData[[#This Row],[Purchase_Price]]+PortfolioData[[#This Row],[Net Operating Income (NOI)]]) / PortfolioData[[#This Row],[Purchase_Price]] -> 0.2228852 | Z18: =_xlfn.PERCENTRANK.INC(PortfolioData[ROI],PortfolioData[[#This Row],[ROI]]) -> 0.483 | AA18: =IF(PortfolioData[[#This Row],[ROI_Percentile]]<=0.1,"Underperforming","Healthy") -> Healthy | AB18: =PortfolioData[[#This Row],[Debt_Outstanding]]/PortfolioData[[#This Row],[Current_Value]] -> 1.0623589 | AC18: =PortfolioData[[#This Row],[Units]]*PortfolioData[[#This Row],[Avg_Rent_per_Unit]]*12 -> 2173224 | AD18: =PortfolioData[[#This Row],[Potential_Revenue]]-PortfolioData[[#This Row],[Gross_Rental_Income]] -> 701040 | AE18: =IFERROR(PortfolioData[[#This Row],[Vacancy_Loss]]/PortfolioData[[#This Row],[Potential_Revenue]],0) -> 0.32258065 | AF18: =(PortfolioData[[#This Row],[Vacancy_%]] * 0.4) + (PortfolioData[[#This Row],[Debt_Ratio]] * 0.3) + (PortfolioData[[#This Row],[Interest_Rate]]/100 * 0.3) -> 0.46378994
A19: P042 | B19: Adelaide | C19: Warehouse | D19: 2017 | E19: 6146954 | F19: 8530117.3 | G19: 77 | H19: 67 | I19: 4699 | J19: 477082 | K19: 421243 | L19: 11283452 | M19: 4.84 | N19: Long-term | O19: =PortfolioData[[#This Row],[Occupied_Units]]*PortfolioData[[#This Row],[Avg_Rent_per_Unit]]*12 -> 3777996 | P19: =1-(PortfolioData[[#This Row],[Occupied_Units]]/PortfolioData[[#This Row],[Units]]) -> 0.12987013 | Q19: =PortfolioData[[#This Row],[Gross_Rental_Income]] - PortfolioData[[#This Row],[Operating_Cost]] - PortfolioData[[#This Row],[Maintenance_Cost]] -> 2879671 | R19: =PortfolioData[[#This Row],[Adjusted_Debt_Outstanding]]*(PortfolioData[[#This Row],[Interest_Rate]]/100) -> 330286.14 | S19: =MIN(PortfolioData[[#This Row],[Debt_Outstanding]], PortfolioData[[#This Row],[Current_Value]]*0.8) -> 6824093.8 | T19: =PortfolioData[[#This Row],[Net Operating Income (NOI)]]/PortfolioData[[#This Row],[Annual_Debt_Service]] -> 8.7187158 | U19: =PortfolioData[[#This Row],[Net Operating Income (NOI)]]-PortfolioData[[#This Row],[Annual_Debt_Service]] -> 2549384.9 | V19: =PortfolioData[[#This Row],[Net Operating Income (NOI)]] -> 2879671 | W19: =PortfolioData[[#This Row],[Gross_Rental_Income]] / PortfolioData[[#This Row],[Purchase_Price]] -> 0.6146127 | X19: =PortfolioData[[#This Row],[Net Operating Income (NOI)]]/PortfolioData[[#This Row],[Current_Value]] -> 0.33758868 | Y19: =(PortfolioData[[#This Row],[Current_Value]]-PortfolioData[[#This Row],[Purchase_Price]]+PortfolioData[[#This Row],[Net Operating Income (NOI)]]) / PortfolioData[[#This Row],[Purchase_Price]] -> 0.85616946 | Z19: =_xlfn.PERCENTRANK.INC(PortfolioData[ROI],PortfolioData[[#This Row],[ROI]]) -> 1 | AA19: =IF(PortfolioData[[#This Row],[ROI_Percentile]]<=0.1,"Underperforming","Healthy") -> Healthy | AB19: =PortfolioData[[#This Row],[Debt_Outstanding]]/PortfolioData[[#This Row],[Current_Value]] -> 1.3227781 | AC19: =PortfolioData[[#This Row],[Units]]*PortfolioData[[#This Row],[Avg_Rent_per_Unit]]*12 -> 4341876 | AD19: =PortfolioData[[#This Row],[Potential_Revenue]]-PortfolioData[[#This Row],[Gross_Rental_Income]] -> 563880 | AE19: =IFERROR(PortfolioData[[#This Row],[Vacancy_Loss]]/PortfolioData[[#This Row],[Potential_Revenue]],0) -> 0.12987013 | AF19: =(PortfolioData[[#This Row],[Vacancy_%]] * 0.4) + (PortfolioData[[#This Row],[Debt_Ratio]] * 0.3) + (PortfolioData[[#This Row],[Interest_Rate]]/100 * 0.3) -> 0.46330147
